try{
//console.log('inside try');
//throw "You are wrong!";
}
catch(err){
    console.log(err);
}
finally{
    console.log('Inside finally');
}